<?xml version="1.0"?>
<robot name="my_robot">

    <!-- Materiales -->
    <material name="green">
        <color rgba="0 0.6 0 1" />
    </material>
    <material name="gray">
        <color rgba="0.7 0.7 0.7 1" />
    </material>

    <!-- Chassis (Caja base) -->
    <link name="base_link">
        <visual>
            <geometry>
                <box size="0.6 0.4 0.2" />
            </geometry>
            <origin xyz="0 0 0.1" rpy="0 0 0" />
            <material name="green" />
        </visual>
    </link>

    <!-- Rueda Derecha -->
    <link name="right_wheel_link">
        <visual>
            <geometry>
                <cylinder radius="0.1" length="0.05" />
            </geometry>
            <!-- Rotamos el cilindro para que ruede sobre el suelo -->
            <origin xyz="0 0 0" rpy="1.5708 0 0" />
            <material name="gray" />
        </visual>
    </link>

    <joint name="base_right_wheel_joint" type="continuous">
        <parent link="base_link" />
        <child link="right_wheel_link" />
        <origin xyz="-0.15 -0.225 0" rpy="0 0 0" />
        <axis xyz="0 1 0" />
    </joint>

    <!-- Rueda Izquierda -->
    <link name="left_wheel_link">
        <visual>
            <geometry>
                <cylinder radius="0.1" length="0.05" />
            </geometry>
            <origin xyz="0 0 0" rpy="1.5708 0 0" />
            <material name="gray" />
        </visual>
    </link>

    <joint name="base_left_wheel_joint" type="continuous">
        <parent link="base_link" />
        <child link="left_wheel_link" />
        <origin xyz="-0.15 0.225 0" rpy="0 0 0" />
        <axis xyz="0 1 0" />
    </joint>

    <!-- Rueda Loca (Caster Wheel) -->
    <link name="caster_wheel_link">
        <visual>
            <geometry>
                <sphere radius="0.05" />
            </geometry>
            <origin xyz="0 0 0" rpy="0 0 0" />
            <material name="gray" />
        </visual>
    </link>

    <joint name="base_caster_wheel_joint" type="fixed">
        <parent link="base_link" />
        <child link="caster_wheel_link" />
        <origin xyz="0.2 0 -0.05" rpy="0 0 0" />
    </joint>

</robot>