<?xml version="1.0"?>
<robot name="carreta_robot">

  <link name="base_footprint"/>

  <joint name="base_footprint_joint" type="fixed">
    <parent link="base_footprint"/>
    <child link="base_link"/>
    <origin xyz="0 0 0" rpy="0 0 0"/>
  </joint>
  <!-- ========== BASE DE LA CARRETA =========== -->

  <link name="base_link">
    <visual>
      <geometry><box size="0.6 0.4 0.2"/></geometry>
      <origin xyz="0 0 0.1" rpy="0 0 0" />
      <material name="green"><color rgba="0 1 0 0.6"/></material>
    </visual>
    <collision>
      <geometry><box size="0.6 0.4 0.2"/></geometry>
      <origin xyz="0 0 0.1" rpy="0 0 0" />
    </collision>
    <inertial>
      <origin xyz="0 0 0.1" rpy="0 0 0" />
      <mass value="5.0"/>
      <inertia ixx="0.083" iyy="0.166" izz="0.216" ixy="0" ixz="0" iyz="0"/>
    </inertial>
  </link>

  <gazebo reference="base_link">
    <material>Gazebo/Green</material>
  </gazebo>
  <!-- ========== RUEDA TRASERA IZQUIERDA =========== -->

  <link name="left_wheel">
    <visual>
      <origin xyz="0 0 0" rpy="1.5708 0 0"/>
      <geometry><cylinder radius="0.1" length="0.05"/></geometry>
      <material name="gray"><color rgba="0.7 0.7 0.7 0.9"/></material>
    </visual>
    <collision>
      <origin xyz="0 0 0" rpy="1.5708 0 0"/>
      <geometry><cylinder radius="0.1" length="0.05"/></geometry>
    </collision>
    <inertial>
      <mass value="1.0"/>
      <inertia ixx="0.0027" iyy="0.0027" izz="0.005" ixy="0" ixz="0" iyz="0"/>
    </inertial>
  </link>

  <joint name="left_wheel_joint" type="revolute">
    <parent link="base_link"/>
    <child link="left_wheel"/>
    <origin xyz="-0.2 0.225 0.1" rpy="0 0 0"/>
    <axis xyz="0 1 0"/>
    <limit lower="-3.14" upper="3.14" effort="100" velocity="10"/>
  </joint>

  <!-- ========== RUEDA TRASERA DERECHA =========== -->

  <link name="right_wheel">
    <visual>
      <origin xyz="0 0 0" rpy="1.5708 0 0"/>
      <geometry><cylinder radius="0.1" length="0.05"/></geometry>
    </visual>
    <collision>
      <origin xyz="0 0 0" rpy="1.5708 0 0"/>
      <geometry><cylinder radius="0.1" length="0.05"/></geometry>
    </collision>
    <inertial>
      <mass value="1.0"/><inertia ixx="0.0027" iyy="0.0027" izz="0.005" ixy="0" ixz="0" iyz="0"/>
    </inertial>
  </link>

  <joint name="right_wheel_joint" type="revolute">
    <parent link="base_link"/><child link="right_wheel"/>
    <origin xyz="-0.2 -0.225 0.1" rpy="0 0 0"/><axis xyz="0 1 0"/>
    <limit lower="-3.14" upper="3.14" effort="100" velocity="10"/>
  </joint>

  <!-- ========== RUEDA DELANTERA IZQUIERDA =========== -->

  <link name="front_left_wheel">
    <visual>
      <origin xyz="0 0 0" rpy="1.5708 0 0"/>
      <geometry><cylinder radius="0.1" length="0.05"/></geometry>
    </visual>
    <collision>
      <origin xyz="0 0 0" rpy="1.5708 0 0"/>
      <geometry><cylinder radius="0.1" length="0.05"/></geometry>
    </collision>
    <inertial>
      <mass value="1.0"/><inertia ixx="0.0027" iyy="0.0027" izz="0.005" ixy="0" ixz="0" iyz="0"/>
    </inertial>
  </link>

  <joint name="front_left_wheel_joint" type="revolute">
    <parent link="base_link"/><child link="front_left_wheel"/>
    <origin xyz="0.2 0.225 0.1" rpy="0 0 0"/><axis xyz="0 1 0"/>
    <limit lower="-3.14" upper="3.14" effort="100" velocity="10"/>
  </joint>

  <!-- ========== RUEDA DELANTERA DERECHA =========== -->

  <link name="front_right_wheel">
    <visual>
      <origin xyz="0 0 0" rpy="1.5708 0 0"/>
      <geometry><cylinder radius="0.1" length="0.05"/></geometry>
    </visual>
    <collision>
      <origin xyz="0 0 0" rpy="1.5708 0 0"/>
      <geometry><cylinder radius="0.1" length="0.05"/></geometry>
    </collision>
    <inertial>
      <mass value="1.0"/><inertia ixx="0.0027" iyy="0.0027" izz="0.005" ixy="0" ixz="0" iyz="0"/>
    </inertial>
  </link>

  <joint name="front_right_wheel_joint" type="revolute">
    <parent link="base_link"/><child link="front_right_wheel"/>
    <origin xyz="0.2 -0.225 0.1" rpy="0 0 0"/><axis xyz="0 1 0"/>
    <limit lower="-3.14" upper="3.14" effort="100" velocity="10"/>
  </joint>
  <gazebo reference="left_wheel"><material>Gazebo/Grey</material><mu1>1.0</mu1><mu2>1.0</mu2></gazebo>
  <gazebo reference="right_wheel"><material>Gazebo/Grey</material><mu1>1.0</mu1><mu2>1.0</mu2></gazebo>
  <gazebo reference="front_left_wheel"><material>Gazebo/Grey</material><mu1>1.0</mu1><mu2>1.0</mu2></gazebo>
  <gazebo reference="front_right_wheel"><material>Gazebo/Grey</material><mu1>1.0</mu1><mu2>1.0</mu2></gazebo>
</robot>
